<?xml version="1.0" ?>
<robot name="arm" xmlns:xacro="http://www.ros.org/wiki/xacro">

    <xacro:include filename="$(find arm_description)/urdf/materials.xacro"/>
    <xacro:property name="PI" value="3.14159265359"/>
    <xacro:property name="effort" value="30"/>
    <xacro:property name="velocity" value="10"/>

    <link name="base_link">
        <inertial>
            <origin xyz="0.0 0.0 0.04999999999999999" rpy="0 0 0"/>
            <mass value="4.454483858479053"/>
            <inertia ixx="0.005724" iyy="0.005724" izz="0.004023" ixy="-0.0" iyz="0.0" ixz="0.0"/>
        </inertial>
        <visual>
            <origin xyz="0 0 0" rpy="0 0 0"/>
            <geometry>
                <mesh filename="file://$(find arm_description)/meshes/base_link.stl" scale="0.001 0.001 0.001"/>
            </geometry>
            <material name="silver"/>
        </visual>
        <collision>
            <origin xyz="0 0 0" rpy="0 0 0"/>
            <geometry>
                <mesh filename="file://$(find arm_description)/meshes/base_link.stl" scale="0.001 0.001 0.001"/>
            </geometry>
        </collision>
    </link>

    <link name="A_link_1_1">
        <inertial>
            <origin xyz="6.566808042589417e-06 -0.01930388604911311 0.015587787508872478" rpy="0 0 0"/>
            <mass value="0.6055706042510981"/>
            <inertia ixx="0.000849" iyy="0.000499" izz="0.000953" ixy="0.0" iyz="0.00022" ixz="-0.0"/>
        </inertial>
        <visual>
            <origin xyz="-0.0 -0.0 -0.1" rpy="0 0 0"/>
            <geometry>
                <mesh filename="file://$(find arm_description)/meshes/A_link_1_1.stl" scale="0.001 0.001 0.001"/>
            </geometry>
            <material name="silver"/>
        </visual>
        <collision>
            <origin xyz="-0.0 -0.0 -0.1" rpy="0 0 0"/>
            <geometry>
                <mesh filename="file://$(find arm_description)/meshes/A_link_1_1.stl" scale="0.001 0.001 0.001"/>
            </geometry>
        </collision>
    </link>

    <link name="mini_1">
        <inertial>
            <origin xyz="-9.611538605247235e-08 0.02749999999999887 -3.570384012052674e-07" rpy="0 0 0"/>
            <mass value="2.4499661221634783"/>
            <inertia ixx="0.001724" iyy="0.002213" izz="0.001724" ixy="-0.0" iyz="0.0" ixz="0.0"/>
        </inertial>
        <visual>
            <origin xyz="-1.8e-05 0.058 -0.160821" rpy="0 0 0"/>
            <geometry>
                <mesh filename="file://$(find arm_description)/meshes/mini_1.stl" scale="0.001 0.001 0.001"/>
            </geometry>
            <material name="silver"/>
        </visual>
        <collision>
            <origin xyz="-1.8e-05 0.058 -0.160821" rpy="0 0 0"/>
            <geometry>
                <mesh filename="file://$(find arm_description)/meshes/mini_1.stl" scale="0.001 0.001 0.001"/>
            </geometry>
        </collision>
    </link>

    <link name="B_link_1_1">
        <inertial>
            <origin xyz="-0.00012611712835024848 0.014973849630638941 0.028499142987686632" rpy="0 0 0"/>
            <mass value="0.8918688582896708"/>
            <inertia ixx="0.001182" iyy="0.001425" izz="0.000442" ixy="1e-06" iyz="-0.000108" ixz="2e-06"/>
        </inertial>
        <visual>
            <origin xyz="-1.8e-05 0.003 -0.160821" rpy="0 0 0"/>
            <geometry>
                <mesh filename="file://$(find arm_description)/meshes/B_link_1_1.stl" scale="0.001 0.001 0.001"/>
            </geometry>
            <material name="silver"/>
        </visual>
        <collision>
            <origin xyz="-1.8e-05 0.003 -0.160821" rpy="0 0 0"/>
            <geometry>
                <mesh filename="file://$(find arm_description)/meshes/B_link_1_1.stl" scale="0.001 0.001 0.001"/>
            </geometry>
        </collision>
    </link>

    <link name="mini_2_1">
        <inertial>
            <origin xyz="1.091950321616532e-07 -9.586228959807398e-08 0.0275000000000008" rpy="0 0 0"/>
            <mass value="2.4499661221634783"/>
            <inertia ixx="0.001724" iyy="0.001724" izz="0.002213" ixy="-0.0" iyz="0.0" ixz="0.0"/>
        </inertial>
        <visual>
            <origin xyz="0.000204 -0.000204 -0.258" rpy="0 0 0"/>
            <geometry>
                <mesh filename="file://$(find arm_description)/meshes/mini_2_1.stl" scale="0.001 0.001 0.001"/>
            </geometry>
            <material name="silver"/>
        </visual>
        <collision>
            <origin xyz="0.000204 -0.000204 -0.258" rpy="0 0 0"/>
            <geometry>
                <mesh filename="file://$(find arm_description)/meshes/mini_2_1.stl" scale="0.001 0.001 0.001"/>
            </geometry>
        </collision>
    </link>

    <link name="A_link_2_1">
        <inertial>
            <origin xyz="6.6760030758991834e-06 -0.01930398191140269 0.015587787508873407" rpy="0 0 0"/>
            <mass value="0.6055706042510981"/>
            <inertia ixx="0.000849" iyy="0.000499" izz="0.000953" ixy="0.0" iyz="0.00022" ixz="-0.0"/>
        </inertial>
        <visual>
            <origin xyz="0.000204 -0.000204 -0.313" rpy="0 0 0"/>
            <geometry>
                <mesh filename="file://$(find arm_description)/meshes/A_link_2_1.stl" scale="0.001 0.001 0.001"/>
            </geometry>
            <material name="silver"/>
        </visual>
        <collision>
            <origin xyz="0.000204 -0.000204 -0.313" rpy="0 0 0"/>
            <geometry>
                <mesh filename="file://$(find arm_description)/meshes/A_link_2_1.stl" scale="0.001 0.001 0.001"/>
            </geometry>
        </collision>
    </link>

    <link name="mini_3_1">
        <inertial>
            <origin xyz="1.3079647242727772e-08 0.02749990413770926 -3.570384003448446e-07" rpy="0 0 0"/>
            <mass value="2.4499661221634783"/>
            <inertia ixx="0.001724" iyy="0.002213" izz="0.001724" ixy="0.0" iyz="-0.0" ixz="0.0"/>
        </inertial>
        <visual>
            <origin xyz="0.000186 0.057796 -0.373821" rpy="0 0 0"/>
            <geometry>
                <mesh filename="file://$(find arm_description)/meshes/mini_3_1.stl" scale="0.001 0.001 0.001"/>
            </geometry>
            <material name="silver"/>
        </visual>
        <collision>
            <origin xyz="0.000186 0.057796 -0.373821" rpy="0 0 0"/>
            <geometry>
                <mesh filename="file://$(find arm_description)/meshes/mini_3_1.stl" scale="0.001 0.001 0.001"/>
            </geometry>
        </collision>
    </link>

    <link name="B_link_v3_1">
        <inertial>
            <origin xyz="0.0017094348522084773 0.013601046562641933 0.03786981102297654" rpy="0 0 0"/>
            <mass value="1.0096188582896708"/>
            <inertia ixx="0.0019" iyy="0.002275" izz="0.000611" ixy="2e-05" iyz="-9e-06" ixz="-0.000164"/>
        </inertial>
        <visual>
            <origin xyz="0.000186 0.002796 -0.373821" rpy="0 0 0"/>
            <geometry>
                <mesh filename="file://$(find arm_description)/meshes/B_link_v3_1.stl" scale="0.001 0.001 0.001"/>
            </geometry>
            <material name="silver"/>
        </visual>
        <collision>
            <origin xyz="0.000186 0.002796 -0.373821" rpy="0 0 0"/>
            <geometry>
                <mesh filename="file://$(find arm_description)/meshes/B_link_v3_1.stl" scale="0.001 0.001 0.001"/>
            </geometry>
        </collision>
    </link>

    <link name="finger_1">
        <inertial>
            <origin xyz="-0.002499781609934429 -1.9172457915646616e-07 0.02499999999999991" rpy="0 0 0"/>
            <mass value="0.03924999999999999"/>
            <inertia ixx="9e-06" iyy="8e-06" izz="1e-06" ixy="0.0" iyz="0.0" ixz="-0.0"/>
        </inertial>
        <visual>
            <origin xyz="-0.044592 -0.000408 -0.476" rpy="0 0 0"/>
            <geometry>
                <mesh filename="file://$(find arm_description)/meshes/finger_1.stl" scale="0.001 0.001 0.001"/>
            </geometry>
            <material name="silver"/>
        </visual>
        <collision>
            <origin xyz="-0.044592 -0.000408 -0.476" rpy="0 0 0"/>
            <geometry>
                <mesh filename="file://$(find arm_description)/meshes/finger_1.stl" scale="0.001 0.001 0.001"/>
            </geometry>
        </collision>
    </link>

    <joint name="waist_joint" type="revolute">
        <origin xyz="0.0 0.0 0.1" rpy="0 0 0"/>
        <parent link="base_link"/>
        <child link="A_link_1_1"/>
        <axis xyz="0.0 0.0 1.0"/>
        <limit lower="-${PI}" upper="${PI}" effort="${effort}" velocity="${velocity}"/>
    </joint>

    <joint name="Rigid 2" type="fixed">
        <origin xyz="1.8e-05 -0.058 0.060821" rpy="0 0 0"/>
        <parent link="A_link_1_1"/>
        <child link="mini_1"/>
    </joint>

    <joint name="shoulder_joint" type="revolute">
        <origin xyz="0.0 0.055 0.0" rpy="0 0 0"/>
        <parent link="mini_1"/>
        <child link="B_link_1_1"/>
        <axis xyz="-0.0 -1.0 0.0"/>
        <limit lower="-1.833" upper="1.833" effort="${effort}" velocity="${velocity}"/>
    </joint>

    <joint name="Rigid 4" type="fixed">
        <origin xyz="-0.000222 0.003204 0.097179" rpy="0 0 0"/>
        <parent link="B_link_1_1"/>
        <child link="mini_2_1"/>
    </joint>

    <joint name="biceptricep_joint" type="revolute">
        <origin xyz="0.0 0.0 0.055" rpy="0 0 0"/>
        <parent link="mini_2_1"/>
        <child link="A_link_2_1"/>
        <axis xyz="0.0 0.0 1.0"/>
        <limit lower="-${PI}" upper="${PI}" effort="${effort}" velocity="${velocity}"/>
    </joint>

    <joint name="Rigid 6" type="fixed">
        <origin xyz="1.8e-05 -0.058 0.060821" rpy="0 0 0"/>
        <parent link="A_link_2_1"/>
        <child link="mini_3_1"/>
    </joint>

    <joint name="forearm_joint" type="revolute">
        <origin xyz="0.0 0.055 0.0" rpy="0 0 0"/>
        <parent link="mini_3_1"/>
        <child link="B_link_v3_1"/>
        <axis xyz="-0.0 -1.0 0.0"/>
        <limit lower="-1.833" upper="1.833" effort="${effort}" velocity="${velocity}"/>
    </joint>

    <joint name="finger_joint" type="prismatic">
        <origin xyz="0.044778 0.003204 0.102179" rpy="0 0 0"/>
        <parent link="B_link_v3_1"/>
        <child link="finger_1"/>
        <axis xyz="1.0 -0.0 0.0"/>
        <limit upper="0.0" lower="-0.09" effort="100" velocity="100"/>
    </joint>

</robot>
