<?xml version="1.0"?>
<robot name="arm" xmlns:xacro="http://www.ros.org/wiki/xacro">

    <xacro:include filename="$(find arm_description)/urdf/materials.xacro" />
    <xacro:include filename="$(find arm_description)/urdf/arm.trans" />
    <xacro:property name="PI" value="3.14159265359" />
    <xacro:property name="effort" value="30" />
    <xacro:property name="velocity" value="10" />
    <link name="world" />
    <link name="base_link">
        <inertial>
            <origin xyz="-7.122570585896167e-18 -7.122570585896167e-18 0.0115" rpy="0 0 0" />
            <mass value="1.2529769489148532" />
            <inertia ixx="0.000747" iyy="0.000747" izz="0.001384" ixy="-0.0" iyz="-0.0" ixz="-0.0" />
        </inertial>
        <visual>
            <origin xyz="0 0 0" rpy="0 0 0" />
            <geometry>
                <mesh filename="file://$(find arm_description)/meshes/base_link.stl"
                    scale="0.001 0.001 0.001" />
            </geometry>
            <material name="silver" />
        </visual>
        <collision>
            <origin xyz="0 0 0" rpy="0 0 0" />
            <geometry>
                <mesh filename="file://$(find arm_description)/meshes/base_link.stl"
                    scale="0.001 0.001 0.001" />
            </geometry>
        </collision>
    </link>

    <!-- base_joint fixes base_link to the environment -->
    <joint name="base_joint" type="fixed">
        <parent link="world" />
        <child link="base_link" />
        <origin xyz="0 0 0" rpy="0 0 0" />
        <axis xyz="0 0 1" />
    </joint>

    <link name="link_1_1">
        <inertial>
            <origin xyz="1.0865459766237383e-16 1.9984014443252817e-17 0.042728114320090264"
                rpy="0 0 0" />
            <mass value="1.4164963986999342" />
            <inertia ixx="0.000964" iyy="0.001818" izz="0.000979" ixy="-0.0" iyz="-0.0" ixz="-0.0" />
        </inertial>
        <visual>
            <origin xyz="-0.0 -0.0 -0.023" rpy="0 0 0" />
            <geometry>
                <mesh filename="file://$(find arm_description)/meshes/link_1_1.stl"
                    scale="0.001 0.001 0.001" />
            </geometry>
            <material name="silver" />
        </visual>
        <collision>
            <origin xyz="-0.0 -0.0 -0.023" rpy="0 0 0" />
            <geometry>
                <mesh filename="file://$(find arm_description)/meshes/link_1_1.stl"
                    scale="0.001 0.001 0.001" />
            </geometry>
        </collision>
    </link>

    <joint name="joint_1" type="revolute">
        <origin xyz="0.0 0.0 0.023" rpy="0 0 0" />
        <parent link="base_link" />
        <child link="link_1_1" />
        <axis xyz="0.0 0.0 1.0" />
        <limit lower="-${PI}" upper="${PI}" effort="${effort}" velocity="${velocity}" />
    </joint>

</robot>