<?xml version="1.0" ?>
<robot name="arm" xmlns:xacro="http://www.ros.org/wiki/xacro">

    <xacro:include filename="$(find arm_description)/urdf/materials.xacro"/>
    <xacro:property name="PI" value="3.14159265359"/>
    <xacro:property name="effort" value="30"/>
    <xacro:property name="velocity" value="10"/>

    <link name="base_link">
        <inertial>
            <origin xyz="9.074472595560118e-06 4.511803636420403e-06 0.06080491772982903" rpy="0 0 0"/>
            <mass value="2.3664474804835818"/>
            <inertia ixx="0.002614" iyy="0.002626" izz="0.001836" ixy="0.0" iyz="0.0" ixz="-0.0"/>
        </inertial>
        <visual>
            <origin xyz="0 0 0" rpy="0 0 0"/>
            <geometry>
                <mesh filename="file://$(find arm_description)/meshes/base_link.stl" scale="0.001 0.001 0.001"/>
            </geometry>
            <material name="silver"/>
        </visual>
        <collision>
            <origin xyz="0 0 0" rpy="0 0 0"/>
            <geometry>
                <mesh filename="file://$(find arm_description)/meshes/base_link.stl" scale="0.001 0.001 0.001"/>
            </geometry>
        </collision>
    </link>

    <link name="A_link_1_1">
        <inertial>
            <origin xyz="6.993896858461139e-06 -0.020891050878909207 0.01653170831443343" rpy="0 0 0"/>
            <mass value="0.5415680642734683"/>
            <inertia ixx="0.000764" iyy="0.000439" izz="0.000814" ixy="0.0" iyz="0.000213" ixz="-0.0"/>
        </inertial>
        <visual>
            <origin xyz="-0.0 -0.0 -0.09999" rpy="0 0 0"/>
            <geometry>
                <mesh filename="file://$(find arm_description)/meshes/A_link_1_1.stl" scale="0.001 0.001 0.001"/>
            </geometry>
            <material name="silver"/>
        </visual>
        <collision>
            <origin xyz="-0.0 -0.0 -0.09999" rpy="0 0 0"/>
            <geometry>
                <mesh filename="file://$(find arm_description)/meshes/A_link_1_1.stl" scale="0.001 0.001 0.001"/>
            </geometry>
        </collision>
    </link>

    <link name="actuator_mini_1_1">
        <inertial>
            <origin xyz="1.2003763611918957e-05 0.0279280052798158 -2.346780126005754e-06" rpy="0 0 0"/>
            <mass value="1.792545854428748"/>
            <inertia ixx="0.001351" iyy="0.001671" izz="0.001352" ixy="0.0" iyz="-0.0" ixz="-0.0"/>
        </inertial>
        <visual>
            <origin xyz="-1.8e-05 0.058 -0.160811" rpy="0 0 0"/>
            <geometry>
                <mesh filename="file://$(find arm_description)/meshes/actuator_mini_1_1.stl" scale="0.001 0.001 0.001"/>
            </geometry>
            <material name="silver"/>
        </visual>
        <collision>
            <origin xyz="-1.8e-05 0.058 -0.160811" rpy="0 0 0"/>
            <geometry>
                <mesh filename="file://$(find arm_description)/meshes/actuator_mini_1_1.stl" scale="0.001 0.001 0.001"/>
            </geometry>
        </collision>
    </link>

    <link name="B_link_1_1">
        <inertial>
            <origin xyz="-0.00011908362991250562 0.014840057092067972 0.02802838695795798" rpy="0 0 0"/>
            <mass value="0.8096607706832739"/>
            <inertia ixx="0.001142" iyy="0.001354" izz="0.000407" ixy="1e-06" iyz="-9.9e-05" ixz="2e-06"/>
        </inertial>
        <visual>
            <origin xyz="-1.8e-05 0.003 -0.160811" rpy="0 0 0"/>
            <geometry>
                <mesh filename="file://$(find arm_description)/meshes/B_link_1_1.stl" scale="0.001 0.001 0.001"/>
            </geometry>
            <material name="silver"/>
        </visual>
        <collision>
            <origin xyz="-1.8e-05 0.003 -0.160811" rpy="0 0 0"/>
            <geometry>
                <mesh filename="file://$(find arm_description)/meshes/B_link_1_1.stl" scale="0.001 0.001 0.001"/>
            </geometry>
        </collision>
    </link>

    <link name="actuator_mini_2_1">
        <inertial>
            <origin xyz="1.2209074028974958e-05 1.8938794354540832e-06 0.027928005279817814" rpy="0 0 0"/>
            <mass value="1.7925458544287485"/>
            <inertia ixx="0.001351" iyy="0.001352" izz="0.001671" ixy="0.0" iyz="0.0" ixz="0.0"/>
        </inertial>
        <visual>
            <origin xyz="0.000204 -0.000204 -0.25799" rpy="0 0 0"/>
            <geometry>
                <mesh filename="file://$(find arm_description)/meshes/actuator_mini_2_1.stl" scale="0.001 0.001 0.001"/>
            </geometry>
            <material name="silver"/>
        </visual>
        <collision>
            <origin xyz="0.000204 -0.000204 -0.25799" rpy="0 0 0"/>
            <geometry>
                <mesh filename="file://$(find arm_description)/meshes/actuator_mini_2_1.stl" scale="0.001 0.001 0.001"/>
            </geometry>
        </collision>
    </link>

    <link name="A_link_2_1">
        <inertial>
            <origin xyz="7.103091889460128e-06 -0.020891146741198668 0.0165317083144344" rpy="0 0 0"/>
            <mass value="0.5415680642734683"/>
            <inertia ixx="0.000764" iyy="0.000439" izz="0.000814" ixy="0.0" iyz="0.000213" ixz="-0.0"/>
        </inertial>
        <visual>
            <origin xyz="0.000204 -0.000204 -0.31299" rpy="0 0 0"/>
            <geometry>
                <mesh filename="file://$(find arm_description)/meshes/A_link_2_1.stl" scale="0.001 0.001 0.001"/>
            </geometry>
            <material name="silver"/>
        </visual>
        <collision>
            <origin xyz="0.000204 -0.000204 -0.31299" rpy="0 0 0"/>
            <geometry>
                <mesh filename="file://$(find arm_description)/meshes/A_link_2_1.stl" scale="0.001 0.001 0.001"/>
            </geometry>
        </collision>
    </link>

    <link name="actuator_mini_3_1">
        <inertial>
            <origin xyz="1.2112958642917918e-05 0.02792790941752636 -2.3467801250065534e-06" rpy="0 0 0"/>
            <mass value="1.792545854428748"/>
            <inertia ixx="0.001351" iyy="0.001671" izz="0.001352" ixy="0.0" iyz="-0.0" ixz="-0.0"/>
        </inertial>
        <visual>
            <origin xyz="0.000186 0.057796 -0.373811" rpy="0 0 0"/>
            <geometry>
                <mesh filename="file://$(find arm_description)/meshes/actuator_mini_3_1.stl" scale="0.001 0.001 0.001"/>
            </geometry>
            <material name="silver"/>
        </visual>
        <collision>
            <origin xyz="0.000186 0.057796 -0.373811" rpy="0 0 0"/>
            <geometry>
                <mesh filename="file://$(find arm_description)/meshes/actuator_mini_3_1.stl" scale="0.001 0.001 0.001"/>
            </geometry>
        </collision>
    </link>

    <link name="B_link_2_1">
        <inertial>
            <origin xyz="-0.00011897443488150664 0.014839961229778542 0.028028386957958895" rpy="0 0 0"/>
            <mass value="0.8096607706832739"/>
            <inertia ixx="0.001142" iyy="0.001354" izz="0.000407" ixy="1e-06" iyz="-9.9e-05" ixz="2e-06"/>
        </inertial>
        <visual>
            <origin xyz="0.000186 0.002796 -0.373811" rpy="0 0 0"/>
            <geometry>
                <mesh filename="file://$(find arm_description)/meshes/B_link_2_1.stl" scale="0.001 0.001 0.001"/>
            </geometry>
            <material name="silver"/>
        </visual>
        <collision>
            <origin xyz="0.000186 0.002796 -0.373811" rpy="0 0 0"/>
            <geometry>
                <mesh filename="file://$(find arm_description)/meshes/B_link_2_1.stl" scale="0.001 0.001 0.001"/>
            </geometry>
        </collision>
    </link>

    <link name="actuator_mini_4_1">
        <inertial>
            <origin xyz="1.2318269059978981e-05 1.7980171460485364e-06 0.027928005279818757" rpy="0 0 0"/>
            <mass value="1.7925458544287487"/>
            <inertia ixx="0.001351" iyy="0.001352" izz="0.001671" ixy="0.0" iyz="0.0" ixz="0.0"/>
        </inertial>
        <visual>
            <origin xyz="0.000408 -0.000408 -0.47099" rpy="0 0 0"/>
            <geometry>
                <mesh filename="file://$(find arm_description)/meshes/actuator_mini_4_1.stl" scale="0.001 0.001 0.001"/>
            </geometry>
            <material name="silver"/>
        </visual>
        <collision>
            <origin xyz="0.000408 -0.000408 -0.47099" rpy="0 0 0"/>
            <geometry>
                <mesh filename="file://$(find arm_description)/meshes/actuator_mini_4_1.stl" scale="0.001 0.001 0.001"/>
            </geometry>
        </collision>
    </link>

    <link name="A_link_v3_1">
        <inertial>
            <origin xyz="7.212286920459056e-06 -0.020891242603488062 0.0165317083144354" rpy="0 0 0"/>
            <mass value="0.5415680642734683"/>
            <inertia ixx="0.000764" iyy="0.000439" izz="0.000814" ixy="0.0" iyz="0.000213" ixz="-0.0"/>
        </inertial>
        <visual>
            <origin xyz="0.000408 -0.000408 -0.52599" rpy="0 0 0"/>
            <geometry>
                <mesh filename="file://$(find arm_description)/meshes/A_link_v3_1.stl" scale="0.001 0.001 0.001"/>
            </geometry>
            <material name="silver"/>
        </visual>
        <collision>
            <origin xyz="0.000408 -0.000408 -0.52599" rpy="0 0 0"/>
            <geometry>
                <mesh filename="file://$(find arm_description)/meshes/A_link_v3_1.stl" scale="0.001 0.001 0.001"/>
            </geometry>
        </collision>
    </link>

    <link name="actuator_mini_v2_1">
        <inertial>
            <origin xyz="1.2222153673901721e-05 0.02792781355523693 -2.346780123785308e-06" rpy="0 0 0"/>
            <mass value="1.7925458544287483"/>
            <inertia ixx="0.001351" iyy="0.001671" izz="0.001352" ixy="0.0" iyz="-0.0" ixz="-0.0"/>
        </inertial>
        <visual>
            <origin xyz="0.00039 0.057592 -0.586811" rpy="0 0 0"/>
            <geometry>
                <mesh filename="file://$(find arm_description)/meshes/actuator_mini_v2_1.stl"
                      scale="0.001 0.001 0.001"/>
            </geometry>
            <material name="silver"/>
        </visual>
        <collision>
            <origin xyz="0.00039 0.057592 -0.586811" rpy="0 0 0"/>
            <geometry>
                <mesh filename="file://$(find arm_description)/meshes/actuator_mini_v2_1.stl"
                      scale="0.001 0.001 0.001"/>
            </geometry>
        </collision>
    </link>

    <link name="B_link_3_1">
        <inertial>
            <origin xyz="-0.0001188652398505349 0.014839865367489106 0.028028386957960394" rpy="0 0 0"/>
            <mass value="0.8096607706832739"/>
            <inertia ixx="0.001142" iyy="0.001354" izz="0.000407" ixy="1e-06" iyz="-9.9e-05" ixz="2e-06"/>
        </inertial>
        <visual>
            <origin xyz="0.00039 0.002592 -0.586811" rpy="0 0 0"/>
            <geometry>
                <mesh filename="file://$(find arm_description)/meshes/B_link_3_1.stl" scale="0.001 0.001 0.001"/>
            </geometry>
            <material name="silver"/>
        </visual>
        <collision>
            <origin xyz="0.00039 0.002592 -0.586811" rpy="0 0 0"/>
            <geometry>
                <mesh filename="file://$(find arm_description)/meshes/B_link_3_1.stl" scale="0.001 0.001 0.001"/>
            </geometry>
        </collision>
    </link>

    <joint name="waist_joint" type="revolute">
        <origin xyz="0.0 0.0 0.09999" rpy="0 0 0"/>
        <parent link="base_link"/>
        <child link="A_link_1_1"/>
        <axis xyz="0.0 0.0 1.0"/>
        <limit lower="-${PI}" upper="${PI}" effort="${effort}" velocity="${velocity}"/>
    </joint>

    <joint name="Rigid 3" type="fixed">
        <origin xyz="1.8e-05 -0.058 0.060821" rpy="0 0 0"/>
        <parent link="A_link_1_1"/>
        <child link="actuator_mini_1_1"/>
    </joint>

    <joint name="shoulder_joint" type="revolute">
        <origin xyz="0.0 0.055 0.0" rpy="0 0 0"/>
        <parent link="actuator_mini_1_1"/>
        <child link="B_link_1_1"/>
        <axis xyz="0.0 1.0 -0.0"/>
        <limit lower="-${PI/2}" upper="${PI/2}" effort="${effort}" velocity="${velocity}"/>
    </joint>

    <joint name="Rigid 7" type="fixed">
        <origin xyz="-0.000222 0.003204 0.097179" rpy="0 0 0"/>
        <parent link="B_link_1_1"/>
        <child link="actuator_mini_2_1"/>
    </joint>

    <joint name="biceptricep_joint" type="revolute">
        <origin xyz="0.0 0.0 0.055" rpy="0 0 0"/>
        <parent link="actuator_mini_2_1"/>
        <child link="A_link_2_1"/>
        <axis xyz="-0.0 0.0 1.0"/>
        <limit lower="-${PI}" upper="${PI}" effort="${effort}" velocity="${velocity}"/>
    </joint>

    <joint name="Rigid 9" type="fixed">
        <origin xyz="1.8e-05 -0.058 0.060821" rpy="0 0 0"/>
        <parent link="A_link_2_1"/>
        <child link="actuator_mini_3_1"/>
    </joint>

    <joint name="forearm_joint" type="revolute">
        <origin xyz="0.0 0.055 0.0" rpy="0 0 0"/>
        <parent link="actuator_mini_3_1"/>
        <child link="B_link_2_1"/>
        <axis xyz="0.0 1.0 -0.0"/>
        <limit lower="-${PI/2}" upper="${PI/2}" effort="${effort}" velocity="${velocity}"/>
    </joint>

    <joint name="Rigid 11" type="fixed">
        <origin xyz="-0.000222 0.003204 0.097179" rpy="0 0 0"/>
        <parent link="B_link_2_1"/>
        <child link="actuator_mini_4_1"/>
    </joint>

    <joint name="wrist_joint" type="revolute">
        <origin xyz="0.0 0.0 0.055" rpy="0 0 0"/>
        <parent link="actuator_mini_4_1"/>
        <child link="A_link_v3_1"/>
        <axis xyz="0.0 0.0 1.0"/>
        <limit lower="-${PI}" upper="${PI}" effort="${effort}" velocity="${velocity}"/>
    </joint>

    <joint name="Rigid 13" type="fixed">
        <origin xyz="1.8e-05 -0.058 0.060821" rpy="0 0 0"/>
        <parent link="A_link_v3_1"/>
        <child link="actuator_mini_v2_1"/>
    </joint>

    <joint name="last_joint" type="revolute">
        <origin xyz="0.0 0.055 0.0" rpy="0 0 0"/>
        <parent link="actuator_mini_v2_1"/>
        <child link="B_link_3_1"/>
        <axis xyz="0.0 1.0 -0.0"/>
        <limit lower="-${PI/2}" upper="${PI/2}" effort="${effort}" velocity="${velocity}"/>
    </joint>


</robot>
